<robot
  name="capstone_robot">
  <link
    name="base_link">
    <inertial>
      <origin
        xyz="-1.402E-18 0.002 0.0061406"
        rpy="0 0 0" />
      <mass
        value="0.07154" />
      <inertia
        ixx="0.00014529"
        ixy="2.2046E-22"
        ixz="-3.4141E-21"
        iyy="0.0002665"
        iyz="-6.4299E-23"
        izz="0.0001214" />
    </inertial>
    <visual>
      <origin
        xyz="0 0 0"
        rpy="0 0 0" />
      <geometry>
        <mesh
          filename="package://capstone_robot/meshes/base_link.STL" />
      </geometry>
      <material
        name="">
        <color
          rgba="0.79216 0.81961 0.93333 1" />
      </material>
    </visual>
    <collision>
      <origin
        xyz="0 0 0"
        rpy="0 0 0" />
      <geometry>
        <mesh
          filename="package://capstone_robot/meshes/base_link.STL" />
      </geometry>
    </collision>
  </link>
  <link
    name="right_motor">
    <inertial>
      <origin
        xyz="-7.9797E-17 0.00072466 0.00054983"
        rpy="0 0 0" />
      <mass
        value="0.003292" />
      <inertia
        ixx="1.7487E-07"
        ixy="1.5395E-09"
        ixz="9.4138E-23"
        iyy="2.0467E-07"
        iyz="-6.2479E-09"
        izz="1.0844E-07" />
    </inertial>
    <visual>
      <origin
        xyz="0 0 0"
        rpy="0 0 0" />
      <geometry>
        <mesh
          filename="package://capstone_robot/meshes/right_motor.STL" />
      </geometry>
      <material
        name="">
        <color
          rgba="0.79216 0.81961 0.93333 1" />
      </material>
    </visual>
    <collision>
      <origin
        xyz="0 0 0"
        rpy="0 0 0" />
      <geometry>
        <mesh
          filename="package://capstone_robot/meshes/right_motor.STL" />
      </geometry>
    </collision>
  </link>
  <joint
    name="base_to_right_motor"
    type="fixed">
    <origin
      xyz="-0.02825 0.025 0.009"
      rpy="1.5708 6.123E-17 1.5708" />
    <parent
      link="base_link" />
    <child
      link="right_motor" />
    <axis
      xyz="0 0 0" />
  </joint>
  <link
    name="right_shaft">
    <inertial>
      <origin
        xyz="0 -0.00018579 0.0049871"
        rpy="0 0 0" />
      <mass
        value="6.8914E-05" />
      <inertia
        ixx="6.0869E-10"
        ixy="3.2312E-27"
        ixz="2.4335E-26"
        iyy="6.2323E-10"
        iyz="6.5664E-12"
        izz="7.8654E-11" />
    </inertial>
    <visual>
      <origin
        xyz="0 0 0"
        rpy="0 0 0" />
      <geometry>
        <mesh
          filename="package://capstone_robot/meshes/right_shaft.STL" />
      </geometry>
      <material
        name="">
        <color
          rgba="0.79216 0.81961 0.93333 1" />
      </material>
    </visual>
    <collision>
      <origin
        xyz="0 0 0"
        rpy="0 0 0" />
      <geometry>
        <mesh
          filename="package://capstone_robot/meshes/right_shaft.STL" />
      </geometry>
    </collision>
  </link>
  <joint
    name="motor_to_right_shaft"
    type="continuous">
    <origin
      xyz="0 0 -0.01585"
      rpy="3.1416 0 -1.6591" />
    <parent
      link="right_motor" />
    <child
      link="right_shaft" />
    <axis
      xyz="0 0 -1" />
  </joint>
  <link
    name="right_wheel">
    <inertial>
      <origin
        xyz="-0.0027007 5.9256E-06 3.4694E-18"
        rpy="0 0 0" />
      <mass
        value="0.018836" />
      <inertia
        ixx="8.3689E-06"
        ixy="-1.1897E-10"
        ixz="8.3106E-22"
        iyy="5.3127E-06"
        iyz="3.4411E-22"
        izz="5.3122E-06" />
    </inertial>
    <visual>
      <origin
        xyz="0 0 0"
        rpy="0 0 0" />
      <geometry>
        <mesh
          filename="package://capstone_robot/meshes/right_wheel.STL" />
      </geometry>
      <material
        name="">
        <color
          rgba="0.79216 0.81961 0.93333 1" />
      </material>
    </visual>
    <collision>
      <origin
        xyz="0 0 0"
        rpy="0 0 0" />
      <geometry>
        <mesh
          filename="package://capstone_robot/meshes/right_wheel.STL" />
      </geometry>
    </collision>
  </link>
  <joint
    name="motor_to_right_wheel"
    type="fixed">
    <origin
      xyz="0 0 0.006425"
      rpy="3.1416 1.5708 0" />
    <parent
      link="right_shaft" />
    <child
      link="right_wheel" />
    <axis
      xyz="0 0 0" />
  </joint>
  <link
    name="right_tire">
    <inertial>
      <origin
        xyz="0.000375 1.7347E-18 6.9389E-18"
        rpy="0 0 0" />
      <mass
        value="0.037047" />
      <inertia
        ixx="3.2559E-05"
        ixy="1.2613E-22"
        ixz="1.0461E-21"
        iyy="1.8229E-05"
        iyz="-8.4703E-22"
        izz="1.8229E-05" />
    </inertial>
    <visual>
      <origin
        xyz="0 0 0"
        rpy="0 0 0" />
      <geometry>
        <mesh
          filename="package://capstone_robot/meshes/right_tire.STL" />
      </geometry>
      <material
        name="">
        <color
          rgba="0.29804 0.29804 0.29804 1" />
      </material>
    </visual>
    <collision>
      <origin
        xyz="0 0 0"
        rpy="0 0 0" />
      <geometry>
        <mesh
          filename="package://capstone_robot/meshes/right_tire.STL" />
      </geometry>
    </collision>
  </link>
  <joint
    name="wheel_to_right_tire"
    type="fixed">
    <origin
      xyz="0 0 0"
      rpy="2.3195 0 0" />
    <parent
      link="right_wheel" />
    <child
      link="right_tire" />
    <axis
      xyz="1 0 0" />
  </joint>
  <link
    name="left_motor">
    <inertial>
      <origin
        xyz="3.1225E-17 0.00072466 -0.0072998"
        rpy="0 0 0" />
      <mass
        value="0.003292" />
      <inertia
        ixx="1.7487E-07"
        ixy="-1.5395E-09"
        ixz="-5.8937E-23"
        iyy="2.0467E-07"
        iyz="6.2479E-09"
        izz="1.0844E-07" />
    </inertial>
    <visual>
      <origin
        xyz="0 0 0"
        rpy="0 0 0" />
      <geometry>
        <mesh
          filename="package://capstone_robot/meshes/left_motor.STL" />
      </geometry>
      <material
        name="">
        <color
          rgba="0.79216 0.81961 0.93333 1" />
      </material>
    </visual>
    <collision>
      <origin
        xyz="0 0 0"
        rpy="0 0 0" />
      <geometry>
        <mesh
          filename="package://capstone_robot/meshes/left_motor.STL" />
      </geometry>
    </collision>
  </link>
  <joint
    name="base_to_left_motor"
    type="fixed">
    <origin
      xyz="0.035 0.025 0.009"
      rpy="1.5708 6.123E-17 1.5708" />
    <parent
      link="base_link" />
    <child
      link="left_motor" />
    <axis
      xyz="0 0 0" />
  </joint>
  <link
    name="left_shaft">
    <inertial>
      <origin
        xyz="-3.4694E-18 -0.00018579 0.0049871"
        rpy="0 0 0" />
      <mass
        value="6.8914E-05" />
      <inertia
        ixx="6.0869E-10"
        ixy="-6.2252E-29"
        ixz="-2.2996E-26"
        iyy="6.2323E-10"
        iyz="6.5664E-12"
        izz="7.8654E-11" />
    </inertial>
    <visual>
      <origin
        xyz="0 0 0"
        rpy="0 0 0" />
      <geometry>
        <mesh
          filename="package://capstone_robot/meshes/left_shaft.STL" />
      </geometry>
      <material
        name="">
        <color
          rgba="0.79216 0.81961 0.93333 1" />
      </material>
    </visual>
    <collision>
      <origin
        xyz="0 0 0"
        rpy="0 0 0" />
      <geometry>
        <mesh
          filename="package://capstone_robot/meshes/left_shaft.STL" />
      </geometry>
    </collision>
  </link>
  <joint
    name="motor_to_left_shaft"
    type="continuous">
    <origin
      xyz="0 0 0.0091"
      rpy="0 0 0" />
    <parent
      link="left_motor" />
    <child
      link="left_shaft" />
    <axis
      xyz="0 0 1" />
  </joint>
  <link
    name="left_wheel">
    <inertial>
      <origin
        xyz="-0.0027007 5.9256E-06 0"
        rpy="0 0 0" />
      <mass
        value="0.018836" />
      <inertia
        ixx="8.3689E-06"
        ixy="-1.1897E-10"
        ixz="7.7735E-22"
        iyy="5.3127E-06"
        iyz="-1.8975E-25"
        izz="5.3122E-06" />
    </inertial>
    <visual>
      <origin
        xyz="0 0 0"
        rpy="0 0 0" />
      <geometry>
        <mesh
          filename="package://capstone_robot/meshes/left_wheel.STL" />
      </geometry>
      <material
        name="">
        <color
          rgba="0.79216 0.81961 0.93333 1" />
      </material>
    </visual>
    <collision>
      <origin
        xyz="0 0 0"
        rpy="0 0 0" />
      <geometry>
        <mesh
          filename="package://capstone_robot/meshes/left_wheel.STL" />
      </geometry>
    </collision>
  </link>
  <joint
    name="shaft_to_left_wheel"
    type="fixed">
    <origin
      xyz="0 0 0.006425"
      rpy="3.1416 1.5708 0" />
    <parent
      link="left_shaft" />
    <child
      link="left_wheel" />
    <axis
      xyz="0 0 0" />
  </joint>
  <link
    name="left_tire">
    <inertial>
      <origin
        xyz="-0.000375 0 0"
        rpy="0 0 0" />
      <mass
        value="0.037047" />
      <inertia
        ixx="3.2559E-05"
        ixy="-7.6407E-38"
        ixz="-3.4108E-23"
        iyy="1.8229E-05"
        iyz="2.1176E-21"
        izz="1.8229E-05" />
    </inertial>
    <visual>
      <origin
        xyz="0 0 0"
        rpy="0 0 0" />
      <geometry>
        <mesh
          filename="package://capstone_robot/meshes/left_tire.STL" />
      </geometry>
      <material
        name="">
        <color
          rgba="0.29804 0.29804 0.29804 1" />
      </material>
    </visual>
    <collision>
      <origin
        xyz="0 0 0"
        rpy="0 0 0" />
      <geometry>
        <mesh
          filename="package://capstone_robot/meshes/left_tire.STL" />
      </geometry>
    </collision>
  </link>
  <joint
    name="wheel_to_left_tire"
    type="fixed">
    <origin
      xyz="0 0 0"
      rpy="-2.0648 0 3.1416" />
    <parent
      link="left_wheel" />
    <child
      link="left_tire" />
    <axis
      xyz="1 0 0" />
  </joint>
  <link
    name="support">
    <inertial>
      <origin
        xyz="-0.049733 0.004 -0.00066873"
        rpy="0 0 0" />
      <mass
        value="0.0051276" />
      <inertia
        ixx="1.4388E-07"
        ixy="1.0567E-24"
        ixz="9.4647E-22"
        iyy="1.3156E-05"
        iyz="-1.7831E-26"
        izz="1.3067E-05" />
    </inertial>
    <visual>
      <origin
        xyz="0 0 0"
        rpy="0 0 0" />
      <geometry>
        <mesh
          filename="package://capstone_robot/meshes/support.STL" />
      </geometry>
      <material
        name="">
        <color
          rgba="0.79216 0.81961 0.93333 1" />
      </material>
    </visual>
    <collision>
      <origin
        xyz="0 0 0"
        rpy="0 0 0" />
      <geometry>
        <mesh
          filename="package://capstone_robot/meshes/support.STL" />
      </geometry>
    </collision>
  </link>
  <joint
    name="base_to_support"
    type="fixed">
    <origin
      xyz="0.049733 -0.050669 -0.008"
      rpy="1.5708 0 0" />
    <parent
      link="base_link" />
    <child
      link="support" />
    <axis
      xyz="0 0 0" />
  </joint>
  <link
    name="caster">
    <inertial>
      <origin
        xyz="0.049733 0.006147 -0.00066854"
        rpy="0 0 0" />
      <mass
        value="0.038393" />
      <inertia
        ixx="1.4039E-06"
        ixy="-9.7621E-20"
        ixz="-2.7424E-21"
        iyy="9.7614E-05"
        iyz="9.041E-12"
        izz="9.7672E-05" />
    </inertial>
    <visual>
      <origin
        xyz="0 0 0"
        rpy="0 0 0" />
      <geometry>
        <mesh
          filename="package://capstone_robot/meshes/caster.STL" />
      </geometry>
      <material
        name="">
        <color
          rgba="0.64706 0.61961 0.58824 1" />
      </material>
    </visual>
    <collision>
      <origin
        xyz="0 0 0"
        rpy="0 0 0" />
      <geometry>
        <mesh
          filename="package://capstone_robot/meshes/caster.STL" />
      </geometry>
    </collision>
  </link>
  <joint
    name="support_to_caster"
    type="fixed">
    <origin
      xyz="0 0 0"
      rpy="0 0 3.1416" />
    <parent
      link="support" />
    <child
      link="caster" />
    <axis
      xyz="0 0 0" />
  </joint>
  <link
    name="case">
    <inertial>
      <origin
        xyz="1.2053E-18 0.045965 5.0016E-18"
        rpy="0 0 0" />
      <mass
        value="0.24273" />
      <inertia
        ixx="0.00083392"
        ixy="2.2158E-19"
        ixz="2.4093E-19"
        iyy="0.001418"
        iyz="-1.1099E-19"
        izz="0.00083392" />
    </inertial>
    <visual>
      <origin
        xyz="0 0 0"
        rpy="0 0 0" />
      <geometry>
        <mesh
          filename="package://capstone_robot/meshes/case.STL" />
      </geometry>
      <material
        name="">
        <color
          rgba="0.79216 0.81961 0.93333 1" />
      </material>
    </visual>
    <collision>
      <origin
        xyz="0 0 0"
        rpy="0 0 0" />
      <geometry>
        <mesh
          filename="package://capstone_robot/meshes/case.STL" />
      </geometry>
    </collision>
  </link>
  <joint
    name="base_to_case"
    type="fixed">
    <origin
      xyz="0 0 0.004"
      rpy="1.5707963267949 0 0" />
    <parent
      link="base_link" />
    <child
      link="case" />
    <axis
      xyz="0 0 0" />
  </joint>
  <link
    name="lidar">
    <inertial>
      <origin
        xyz="-2.568E-35 0.0093491 -8.7287E-19"
        rpy="0 0 0" />
      <mass
        value="0.0362" />
      <inertia
        ixx="6.4264E-06"
        ixy="-1.093E-38"
        ixz="-3.1232E-38"
        iyy="1.0649E-05"
        iyz="-2.6259E-22"
        izz="6.4264E-06" />
    </inertial>
    <visual>
      <origin
        xyz="0 0 0"
        rpy="0 0 0" />
      <geometry>
        <mesh
          filename="package://capstone_robot/meshes/lidar.STL" />
      </geometry>
      <material
        name="">
        <color
          rgba="0.79216 0.81961 0.93333 1" />
      </material>
    </visual>
    <collision>
      <origin
        xyz="0 0 0"
        rpy="0 0 0" />
      <geometry>
        <mesh
          filename="package://capstone_robot/meshes/lidar.STL" />
      </geometry>
    </collision>
  </link>
  <joint
    name="case_to_lidar"
    type="fixed">
    <origin
      xyz="0 0.07 0"
      rpy="0 0 0" />
    <parent
      link="case" />
    <child
      link="lidar" />
    <axis
      xyz="0 0 0" />
  </joint>

  <gazebo regerence="base_link">
    <material>Gazebo/Blue</material>
  </gazebo>

  <gazebo regerence="left_tire">
    <material>Gazebo/Black</material>
  </gazebo>

  <gazebo regerence="right_tire">
    <material>Gazebo/Black</material>
  </gazebo>

  <gazebo regerence="left_wheel">
    <material>Gazebo/White</material>
  </gazebo>

  <gazebo regerence="right_wheel">
    <material>Gazebo/White</material>
  </gazebo>

  <gazebo>
    <plugin name="capstone_control" filename="libgazebo_ros_diff_drive.so">
      <alwaysOn>true</alwaysOn>
      <updateRate>20</updateRate>
      <legacyMode>false</legacyMode>
      <leftJoint>motor_to_left_shaft</leftJoint>
      <rightJoint>motor_to_right_shaft</rightJoint>
      <wheelSeparation>0.1</wheelSeparation>
      <wheelDiameter>0.022</wheelDiameter>
      <wheelTorque>0.7</wheelTorque>
      <wheelAcceleration>1</wheelAcceleration>
      <commandTopic>cmd_vel</commandTopic>
      <odometryTopic>odom</odometryTopic>
      <odometryFrame>odom</odometryFrame>
      <odometrySource>world</odometrySource>
      <publishOdomTF>true</publishOdomTF>
      <publishWheelJointState>true</publishWheelJointState>
      <publishWheelTF>false</publishWheelTF>
      <publishTf>true</publishTf>
      <robotBaseFrame>base</robotBaseFrame>
      <rosDebugLevel>na</rosDebugLevel>
    </plugin>
  </gazebo>

</robot>